[2024-12-19T14:13:12.450+0900] {taskinstance.py:1157} INFO - Dependencies all met for dep_context=non-requeueable deps ti=<TaskInstance: dag_crawling_to_db.post_crawl manual__2024-12-19T05:11:37.026996+00:00 [queued]>
[2024-12-19T14:13:12.461+0900] {taskinstance.py:1157} INFO - Dependencies all met for dep_context=requeueable deps ti=<TaskInstance: dag_crawling_to_db.post_crawl manual__2024-12-19T05:11:37.026996+00:00 [queued]>
[2024-12-19T14:13:12.461+0900] {taskinstance.py:1359} INFO - Starting attempt 2 of 2
[2024-12-19T14:13:12.475+0900] {taskinstance.py:1380} INFO - Executing <Task(PythonOperator): post_crawl> on 2024-12-19 05:11:37.026996+00:00
[2024-12-19T14:13:12.478+0900] {standard_task_runner.py:57} INFO - Started process 1437 to run task
[2024-12-19T14:13:12.481+0900] {standard_task_runner.py:84} INFO - Running: ['***', 'tasks', 'run', 'dag_crawling_to_db', 'post_crawl', 'manual__2024-12-19T05:11:37.026996+00:00', '--job-id', '15', '--raw', '--subdir', 'DAGS_FOLDER/dag_crawling_to_db.py', '--cfg-path', '/tmp/tmpw6vxbdss']
[2024-12-19T14:13:12.483+0900] {standard_task_runner.py:85} INFO - Job 15: Subtask post_crawl
[2024-12-19T14:13:12.530+0900] {task_command.py:415} INFO - Running <TaskInstance: dag_crawling_to_db.post_crawl manual__2024-12-19T05:11:37.026996+00:00 [running]> on host 9e2fe3889768
[2024-12-19T14:13:12.609+0900] {taskinstance.py:1660} INFO - Exporting env vars: AIRFLOW_CTX_DAG_OWNER='***' AIRFLOW_CTX_DAG_ID='dag_crawling_to_db' AIRFLOW_CTX_TASK_ID='post_crawl' AIRFLOW_CTX_EXECUTION_DATE='2024-12-19T05:11:37.026996+00:00' AIRFLOW_CTX_TRY_NUMBER='2' AIRFLOW_CTX_DAG_RUN_ID='manual__2024-12-19T05:11:37.026996+00:00'
[2024-12-19T14:13:12.610+0900] {logging_mixin.py:151} INFO - 점핏 시작 시간: 2024-12-19 14:13:12
[2024-12-19T14:13:12.624+0900] {credentials.py:1254} INFO - Found credentials in shared credentials file: /code/.aws/credentials
[2024-12-19T14:13:13.032+0900] {logging_mixin.py:151} INFO - Error reading file from S3: An error occurred (NoSuchKey) when calling the GetObject operation: The specified key does not exist.
[2024-12-19T14:13:13.132+0900] {logger.py:11} INFO - ====== WebDriver manager ======
[2024-12-19T14:13:13.212+0900] {logger.py:11} INFO - Get LATEST chromedriver version for google-chrome
[2024-12-19T14:13:13.283+0900] {logger.py:11} INFO - Get LATEST chromedriver version for google-chrome
[2024-12-19T14:13:13.357+0900] {logger.py:11} INFO - Driver [/home/***/.wdm/drivers/chromedriver/linux64/131.0.6778.204/chromedriver-linux64/chromedriver] found in cache
[2024-12-19T14:13:13.596+0900] {taskinstance.py:1935} ERROR - Task failed with exception
Traceback (most recent call last):
  File "/home/airflow/.local/lib/python3.10/site-packages/airflow/operators/python.py", line 192, in execute
    return_value = self.execute_callable()
  File "/home/airflow/.local/lib/python3.10/site-packages/airflow/operators/python.py", line 209, in execute_callable
    return self.python_callable(*self.op_args, **self.op_kwargs)
  File "/code/plugins/post_crawling.py", line 1909, in post_main
    jumpit_crawling()
  File "/code/plugins/post_crawling.py", line 157, in jumpit_crawling
    driver = webdriver.Chrome(service=Service(ChromeDriverManager().install()), options=options)
  File "/home/airflow/.local/lib/python3.10/site-packages/selenium/webdriver/chrome/webdriver.py", line 45, in __init__
    super().__init__(
  File "/home/airflow/.local/lib/python3.10/site-packages/selenium/webdriver/chromium/webdriver.py", line 66, in __init__
    super().__init__(command_executor=executor, options=options)
  File "/home/airflow/.local/lib/python3.10/site-packages/selenium/webdriver/remote/webdriver.py", line 241, in __init__
    self.start_session(capabilities)
  File "/home/airflow/.local/lib/python3.10/site-packages/selenium/webdriver/remote/webdriver.py", line 329, in start_session
    response = self.execute(Command.NEW_SESSION, caps)["value"]
  File "/home/airflow/.local/lib/python3.10/site-packages/selenium/webdriver/remote/webdriver.py", line 384, in execute
    self.error_handler.check_response(response)
  File "/home/airflow/.local/lib/python3.10/site-packages/selenium/webdriver/remote/errorhandler.py", line 232, in check_response
    raise exception_class(message, screen, stacktrace)
selenium.common.exceptions.SessionNotCreatedException: Message: session not created: Chrome failed to start: exited normally.
  (session not created: DevToolsActivePort file doesn't exist)
  (The process started from chrome location /opt/google/chrome/chrome is no longer running, so ChromeDriver is assuming that Chrome has crashed.)
Stacktrace:
#0 0x5601a50328fa <unknown>
#1 0x5601a4b43d20 <unknown>
#2 0x5601a4b7b438 <unknown>
#3 0x5601a4b76f96 <unknown>
#4 0x5601a4bc2d86 <unknown>
#5 0x5601a4bc23d6 <unknown>
#6 0x5601a4bb6893 <unknown>
#7 0x5601a4b8530d <unknown>
#8 0x5601a4b8632e <unknown>
#9 0x5601a4fff00b <unknown>
#10 0x5601a5002f97 <unknown>
#11 0x5601a4feb71c <unknown>
#12 0x5601a5003b17 <unknown>
#13 0x5601a4fd06cf <unknown>
#14 0x5601a50216b8 <unknown>
#15 0x5601a5021880 <unknown>
#16 0x5601a5031776 <unknown>
#17 0x7f0357f63ea7 start_thread

[2024-12-19T14:13:13.608+0900] {taskinstance.py:1398} INFO - Marking task as FAILED. dag_id=dag_crawling_to_db, task_id=post_crawl, execution_date=20241219T051137, start_date=20241219T051312, end_date=20241219T051313
[2024-12-19T14:13:13.619+0900] {standard_task_runner.py:104} ERROR - Failed to execute job 15 for task post_crawl (Message: session not created: Chrome failed to start: exited normally.
  (session not created: DevToolsActivePort file doesn't exist)
  (The process started from chrome location /opt/google/chrome/chrome is no longer running, so ChromeDriver is assuming that Chrome has crashed.)
Stacktrace:
#0 0x5601a50328fa <unknown>
#1 0x5601a4b43d20 <unknown>
#2 0x5601a4b7b438 <unknown>
#3 0x5601a4b76f96 <unknown>
#4 0x5601a4bc2d86 <unknown>
#5 0x5601a4bc23d6 <unknown>
#6 0x5601a4bb6893 <unknown>
#7 0x5601a4b8530d <unknown>
#8 0x5601a4b8632e <unknown>
#9 0x5601a4fff00b <unknown>
#10 0x5601a5002f97 <unknown>
#11 0x5601a4feb71c <unknown>
#12 0x5601a5003b17 <unknown>
#13 0x5601a4fd06cf <unknown>
#14 0x5601a50216b8 <unknown>
#15 0x5601a5021880 <unknown>
#16 0x5601a5031776 <unknown>
#17 0x7f0357f63ea7 start_thread
; 1437)
[2024-12-19T14:13:13.660+0900] {local_task_job_runner.py:228} INFO - Task exited with return code 1
[2024-12-19T14:13:13.696+0900] {taskinstance.py:2776} INFO - 0 downstream tasks scheduled from follow-on schedule check
