[2024-12-19T16:25:16.218+0900] {taskinstance.py:1157} INFO - Dependencies all met for dep_context=non-requeueable deps ti=<TaskInstance: dag_crawling_to_db.post_crawl manual__2024-12-19T07:23:28+00:00 [queued]>
[2024-12-19T16:25:16.229+0900] {taskinstance.py:1157} INFO - Dependencies all met for dep_context=requeueable deps ti=<TaskInstance: dag_crawling_to_db.post_crawl manual__2024-12-19T07:23:28+00:00 [queued]>
[2024-12-19T16:25:16.229+0900] {taskinstance.py:1359} INFO - Starting attempt 2 of 2
[2024-12-19T16:25:16.243+0900] {taskinstance.py:1380} INFO - Executing <Task(PythonOperator): post_crawl> on 2024-12-19 07:23:28+00:00
[2024-12-19T16:25:16.247+0900] {standard_task_runner.py:57} INFO - Started process 185 to run task
[2024-12-19T16:25:16.250+0900] {standard_task_runner.py:84} INFO - Running: ['***', 'tasks', 'run', 'dag_crawling_to_db', 'post_crawl', 'manual__2024-12-19T07:23:28+00:00', '--job-id', '5', '--raw', '--subdir', 'DAGS_FOLDER/dag_crawling_to_db.py', '--cfg-path', '/tmp/tmpvqrtgn6v']
[2024-12-19T16:25:16.252+0900] {standard_task_runner.py:85} INFO - Job 5: Subtask post_crawl
[2024-12-19T16:25:16.295+0900] {task_command.py:415} INFO - Running <TaskInstance: dag_crawling_to_db.post_crawl manual__2024-12-19T07:23:28+00:00 [running]> on host 2d976db78b57
[2024-12-19T16:25:16.364+0900] {taskinstance.py:1660} INFO - Exporting env vars: AIRFLOW_CTX_DAG_OWNER='***' AIRFLOW_CTX_DAG_ID='dag_crawling_to_db' AIRFLOW_CTX_TASK_ID='post_crawl' AIRFLOW_CTX_EXECUTION_DATE='2024-12-19T07:23:28+00:00' AIRFLOW_CTX_TRY_NUMBER='2' AIRFLOW_CTX_DAG_RUN_ID='manual__2024-12-19T07:23:28+00:00'
[2024-12-19T16:25:16.365+0900] {logging_mixin.py:151} INFO - 점핏 시작 시간: 2024-12-19 16:25:16
[2024-12-19T16:25:16.366+0900] {logging_mixin.py:151} INFO - 점핏 종료 시간: 2024-12-19 16:25:16
[2024-12-19T16:25:26.373+0900] {logging_mixin.py:151} INFO - 원티드 시작 시간: 2024-12-19 16:25:26
[2024-12-19T16:25:26.394+0900] {credentials.py:1254} INFO - Found credentials in shared credentials file: /code/.aws/credentials
[2024-12-19T16:25:26.700+0900] {logger.py:11} INFO - ====== WebDriver manager ======
[2024-12-19T16:25:26.789+0900] {logger.py:11} INFO - Get LATEST chromedriver version for google-chrome
[2024-12-19T16:25:26.866+0900] {logger.py:11} INFO - Get LATEST chromedriver version for google-chrome
[2024-12-19T16:25:26.950+0900] {logger.py:11} INFO - Driver [/home/***/.wdm/drivers/chromedriver/linux64/131.0.6778.204/chromedriver-linux64/chromedriver] found in cache
[2024-12-19T16:25:27.187+0900] {taskinstance.py:1935} ERROR - Task failed with exception
Traceback (most recent call last):
  File "/home/airflow/.local/lib/python3.10/site-packages/airflow/operators/python.py", line 192, in execute
    return_value = self.execute_callable()
  File "/home/airflow/.local/lib/python3.10/site-packages/airflow/operators/python.py", line 209, in execute_callable
    return self.python_callable(*self.op_args, **self.op_kwargs)
  File "/code/plugins/post_crawling.py", line 1920, in post_main
    wanted_crawling()
  File "/code/plugins/post_crawling.py", line 279, in wanted_crawling
    driver = webdriver.Chrome(service=Service(ChromeDriverManager().install()))
  File "/home/airflow/.local/lib/python3.10/site-packages/selenium/webdriver/chrome/webdriver.py", line 45, in __init__
    super().__init__(
  File "/home/airflow/.local/lib/python3.10/site-packages/selenium/webdriver/chromium/webdriver.py", line 66, in __init__
    super().__init__(command_executor=executor, options=options)
  File "/home/airflow/.local/lib/python3.10/site-packages/selenium/webdriver/remote/webdriver.py", line 241, in __init__
    self.start_session(capabilities)
  File "/home/airflow/.local/lib/python3.10/site-packages/selenium/webdriver/remote/webdriver.py", line 329, in start_session
    response = self.execute(Command.NEW_SESSION, caps)["value"]
  File "/home/airflow/.local/lib/python3.10/site-packages/selenium/webdriver/remote/webdriver.py", line 384, in execute
    self.error_handler.check_response(response)
  File "/home/airflow/.local/lib/python3.10/site-packages/selenium/webdriver/remote/errorhandler.py", line 232, in check_response
    raise exception_class(message, screen, stacktrace)
selenium.common.exceptions.SessionNotCreatedException: Message: session not created: Chrome failed to start: exited normally.
  (session not created: DevToolsActivePort file doesn't exist)
  (The process started from chrome location /opt/google/chrome/chrome is no longer running, so ChromeDriver is assuming that Chrome has crashed.)
Stacktrace:
#0 0x55b4dc0498fa <unknown>
#1 0x55b4dbb5ad20 <unknown>
#2 0x55b4dbb92438 <unknown>
#3 0x55b4dbb8df96 <unknown>
#4 0x55b4dbbd9d86 <unknown>
#5 0x55b4dbbd93d6 <unknown>
#6 0x55b4dbbcd893 <unknown>
#7 0x55b4dbb9c30d <unknown>
#8 0x55b4dbb9d32e <unknown>
#9 0x55b4dc01600b <unknown>
#10 0x55b4dc019f97 <unknown>
#11 0x55b4dc00271c <unknown>
#12 0x55b4dc01ab17 <unknown>
#13 0x55b4dbfe76cf <unknown>
#14 0x55b4dc0386b8 <unknown>
#15 0x55b4dc038880 <unknown>
#16 0x55b4dc048776 <unknown>
#17 0x7fda4a756ea7 start_thread

[2024-12-19T16:25:27.196+0900] {taskinstance.py:1398} INFO - Marking task as FAILED. dag_id=dag_crawling_to_db, task_id=post_crawl, execution_date=20241219T072328, start_date=20241219T072516, end_date=20241219T072527
[2024-12-19T16:25:27.208+0900] {standard_task_runner.py:104} ERROR - Failed to execute job 5 for task post_crawl (Message: session not created: Chrome failed to start: exited normally.
  (session not created: DevToolsActivePort file doesn't exist)
  (The process started from chrome location /opt/google/chrome/chrome is no longer running, so ChromeDriver is assuming that Chrome has crashed.)
Stacktrace:
#0 0x55b4dc0498fa <unknown>
#1 0x55b4dbb5ad20 <unknown>
#2 0x55b4dbb92438 <unknown>
#3 0x55b4dbb8df96 <unknown>
#4 0x55b4dbbd9d86 <unknown>
#5 0x55b4dbbd93d6 <unknown>
#6 0x55b4dbbcd893 <unknown>
#7 0x55b4dbb9c30d <unknown>
#8 0x55b4dbb9d32e <unknown>
#9 0x55b4dc01600b <unknown>
#10 0x55b4dc019f97 <unknown>
#11 0x55b4dc00271c <unknown>
#12 0x55b4dc01ab17 <unknown>
#13 0x55b4dbfe76cf <unknown>
#14 0x55b4dc0386b8 <unknown>
#15 0x55b4dc038880 <unknown>
#16 0x55b4dc048776 <unknown>
#17 0x7fda4a756ea7 start_thread
; 185)
[2024-12-19T16:25:27.260+0900] {local_task_job_runner.py:228} INFO - Task exited with return code 1
[2024-12-19T16:25:27.280+0900] {taskinstance.py:2776} INFO - 0 downstream tasks scheduled from follow-on schedule check
