[2024-12-19T16:15:19.743+0900] {taskinstance.py:1157} INFO - Dependencies all met for dep_context=non-requeueable deps ti=<TaskInstance: dag_crawling_to_db.post_crawl manual__2024-12-19T05:14:28+00:00 [queued]>
[2024-12-19T16:15:19.752+0900] {taskinstance.py:1157} INFO - Dependencies all met for dep_context=requeueable deps ti=<TaskInstance: dag_crawling_to_db.post_crawl manual__2024-12-19T05:14:28+00:00 [queued]>
[2024-12-19T16:15:19.752+0900] {taskinstance.py:1359} INFO - Starting attempt 26 of 26
[2024-12-19T16:15:19.766+0900] {taskinstance.py:1380} INFO - Executing <Task(PythonOperator): post_crawl> on 2024-12-19 05:14:28+00:00
[2024-12-19T16:15:19.770+0900] {standard_task_runner.py:57} INFO - Started process 2389 to run task
[2024-12-19T16:15:19.775+0900] {standard_task_runner.py:84} INFO - Running: ['***', 'tasks', 'run', 'dag_crawling_to_db', 'post_crawl', 'manual__2024-12-19T05:14:28+00:00', '--job-id', '31', '--raw', '--subdir', 'DAGS_FOLDER/dag_crawling_to_db.py', '--cfg-path', '/tmp/tmpdosc1hc6']
[2024-12-19T16:15:19.777+0900] {standard_task_runner.py:85} INFO - Job 31: Subtask post_crawl
[2024-12-19T16:15:19.820+0900] {task_command.py:415} INFO - Running <TaskInstance: dag_crawling_to_db.post_crawl manual__2024-12-19T05:14:28+00:00 [running]> on host 937402c51523
[2024-12-19T16:15:19.890+0900] {taskinstance.py:1660} INFO - Exporting env vars: AIRFLOW_CTX_DAG_OWNER='***' AIRFLOW_CTX_DAG_ID='dag_crawling_to_db' AIRFLOW_CTX_TASK_ID='post_crawl' AIRFLOW_CTX_EXECUTION_DATE='2024-12-19T05:14:28+00:00' AIRFLOW_CTX_TRY_NUMBER='26' AIRFLOW_CTX_DAG_RUN_ID='manual__2024-12-19T05:14:28+00:00'
[2024-12-19T16:15:19.890+0900] {logging_mixin.py:151} INFO - 점핏 시작 시간: 2024-12-19 16:15:19
[2024-12-19T16:15:19.905+0900] {credentials.py:1254} INFO - Found credentials in shared credentials file: /code/.aws/credentials
[2024-12-19T16:15:20.290+0900] {logging_mixin.py:151} INFO - Error reading file from S3: An error occurred (NoSuchKey) when calling the GetObject operation: The specified key does not exist.
[2024-12-19T16:15:20.421+0900] {logger.py:11} INFO - ====== WebDriver manager ======
[2024-12-19T16:15:20.478+0900] {logger.py:11} INFO - Get LATEST chromedriver version for google-chrome
[2024-12-19T16:15:20.544+0900] {logger.py:11} INFO - Get LATEST chromedriver version for google-chrome
[2024-12-19T16:15:20.609+0900] {logger.py:11} INFO - Driver [/home/***/.wdm/drivers/chromedriver/linux64/131.0.6778.204/chromedriver-linux64/chromedriver] found in cache
[2024-12-19T16:15:20.848+0900] {taskinstance.py:1935} ERROR - Task failed with exception
Traceback (most recent call last):
  File "/home/airflow/.local/lib/python3.10/site-packages/airflow/operators/python.py", line 192, in execute
    return_value = self.execute_callable()
  File "/home/airflow/.local/lib/python3.10/site-packages/airflow/operators/python.py", line 209, in execute_callable
    return self.python_callable(*self.op_args, **self.op_kwargs)
  File "/code/plugins/post_crawling.py", line 1909, in post_main
    # 실행
  File "/code/plugins/post_crawling.py", line 157, in jumpit_crawling
    options = Options()
  File "/home/airflow/.local/lib/python3.10/site-packages/selenium/webdriver/chrome/webdriver.py", line 45, in __init__
    super().__init__(
  File "/home/airflow/.local/lib/python3.10/site-packages/selenium/webdriver/chromium/webdriver.py", line 66, in __init__
    super().__init__(command_executor=executor, options=options)
  File "/home/airflow/.local/lib/python3.10/site-packages/selenium/webdriver/remote/webdriver.py", line 241, in __init__
    self.start_session(capabilities)
  File "/home/airflow/.local/lib/python3.10/site-packages/selenium/webdriver/remote/webdriver.py", line 329, in start_session
    response = self.execute(Command.NEW_SESSION, caps)["value"]
  File "/home/airflow/.local/lib/python3.10/site-packages/selenium/webdriver/remote/webdriver.py", line 384, in execute
    self.error_handler.check_response(response)
  File "/home/airflow/.local/lib/python3.10/site-packages/selenium/webdriver/remote/errorhandler.py", line 232, in check_response
    raise exception_class(message, screen, stacktrace)
selenium.common.exceptions.SessionNotCreatedException: Message: session not created: Chrome failed to start: exited normally.
  (session not created: DevToolsActivePort file doesn't exist)
  (The process started from chrome location /opt/google/chrome/chrome is no longer running, so ChromeDriver is assuming that Chrome has crashed.)
Stacktrace:
#0 0x5595e097c8fa <unknown>
#1 0x5595e048dd20 <unknown>
#2 0x5595e04c5438 <unknown>
#3 0x5595e04c0f96 <unknown>
#4 0x5595e050cd86 <unknown>
#5 0x5595e050c3d6 <unknown>
#6 0x5595e0500893 <unknown>
#7 0x5595e04cf30d <unknown>
#8 0x5595e04d032e <unknown>
#9 0x5595e094900b <unknown>
#10 0x5595e094cf97 <unknown>
#11 0x5595e093571c <unknown>
#12 0x5595e094db17 <unknown>
#13 0x5595e091a6cf <unknown>
#14 0x5595e096b6b8 <unknown>
#15 0x5595e096b880 <unknown>
#16 0x5595e097b776 <unknown>
#17 0x7f475e496ea7 start_thread

[2024-12-19T16:15:20.857+0900] {taskinstance.py:1398} INFO - Marking task as FAILED. dag_id=dag_crawling_to_db, task_id=post_crawl, execution_date=20241219T051428, start_date=20241219T071519, end_date=20241219T071520
[2024-12-19T16:15:20.870+0900] {standard_task_runner.py:104} ERROR - Failed to execute job 31 for task post_crawl (Message: session not created: Chrome failed to start: exited normally.
  (session not created: DevToolsActivePort file doesn't exist)
  (The process started from chrome location /opt/google/chrome/chrome is no longer running, so ChromeDriver is assuming that Chrome has crashed.)
Stacktrace:
#0 0x5595e097c8fa <unknown>
#1 0x5595e048dd20 <unknown>
#2 0x5595e04c5438 <unknown>
#3 0x5595e04c0f96 <unknown>
#4 0x5595e050cd86 <unknown>
#5 0x5595e050c3d6 <unknown>
#6 0x5595e0500893 <unknown>
#7 0x5595e04cf30d <unknown>
#8 0x5595e04d032e <unknown>
#9 0x5595e094900b <unknown>
#10 0x5595e094cf97 <unknown>
#11 0x5595e093571c <unknown>
#12 0x5595e094db17 <unknown>
#13 0x5595e091a6cf <unknown>
#14 0x5595e096b6b8 <unknown>
#15 0x5595e096b880 <unknown>
#16 0x5595e097b776 <unknown>
#17 0x7f475e496ea7 start_thread
; 2389)
[2024-12-19T16:15:20.914+0900] {local_task_job_runner.py:228} INFO - Task exited with return code 1
[2024-12-19T16:15:20.957+0900] {taskinstance.py:2776} INFO - 0 downstream tasks scheduled from follow-on schedule check
