[2024-12-19T15:04:02.894+0900] {taskinstance.py:1157} INFO - Dependencies all met for dep_context=non-requeueable deps ti=<TaskInstance: dag_crawling_to_db.post_crawl manual__2024-12-19T05:14:28+00:00 [queued]>
[2024-12-19T15:04:02.904+0900] {taskinstance.py:1157} INFO - Dependencies all met for dep_context=requeueable deps ti=<TaskInstance: dag_crawling_to_db.post_crawl manual__2024-12-19T05:14:28+00:00 [queued]>
[2024-12-19T15:04:02.904+0900] {taskinstance.py:1359} INFO - Starting attempt 7 of 8
[2024-12-19T15:04:02.917+0900] {taskinstance.py:1380} INFO - Executing <Task(PythonOperator): post_crawl> on 2024-12-19 05:14:28+00:00
[2024-12-19T15:04:02.923+0900] {standard_task_runner.py:57} INFO - Started process 863 to run task
[2024-12-19T15:04:02.926+0900] {standard_task_runner.py:84} INFO - Running: ['***', 'tasks', 'run', 'dag_crawling_to_db', 'post_crawl', 'manual__2024-12-19T05:14:28+00:00', '--job-id', '10', '--raw', '--subdir', 'DAGS_FOLDER/dag_crawling_to_db.py', '--cfg-path', '/tmp/tmpnj1itg7n']
[2024-12-19T15:04:02.928+0900] {standard_task_runner.py:85} INFO - Job 10: Subtask post_crawl
[2024-12-19T15:04:02.972+0900] {task_command.py:415} INFO - Running <TaskInstance: dag_crawling_to_db.post_crawl manual__2024-12-19T05:14:28+00:00 [running]> on host 937402c51523
[2024-12-19T15:04:03.044+0900] {taskinstance.py:1660} INFO - Exporting env vars: AIRFLOW_CTX_DAG_OWNER='***' AIRFLOW_CTX_DAG_ID='dag_crawling_to_db' AIRFLOW_CTX_TASK_ID='post_crawl' AIRFLOW_CTX_EXECUTION_DATE='2024-12-19T05:14:28+00:00' AIRFLOW_CTX_TRY_NUMBER='7' AIRFLOW_CTX_DAG_RUN_ID='manual__2024-12-19T05:14:28+00:00'
[2024-12-19T15:04:03.045+0900] {logging_mixin.py:151} INFO - 점핏 시작 시간: 2024-12-19 15:04:03
[2024-12-19T15:04:03.062+0900] {credentials.py:1254} INFO - Found credentials in shared credentials file: /code/.aws/credentials
[2024-12-19T15:04:03.485+0900] {logging_mixin.py:151} INFO - Error reading file from S3: An error occurred (NoSuchKey) when calling the GetObject operation: The specified key does not exist.
[2024-12-19T15:04:03.623+0900] {logger.py:11} INFO - ====== WebDriver manager ======
[2024-12-19T15:04:03.701+0900] {logger.py:11} INFO - Get LATEST chromedriver version for google-chrome
[2024-12-19T15:04:03.775+0900] {logger.py:11} INFO - Get LATEST chromedriver version for google-chrome
[2024-12-19T15:04:03.861+0900] {logger.py:11} INFO - Driver [/home/***/.wdm/drivers/chromedriver/linux64/131.0.6778.204/chromedriver-linux64/chromedriver] found in cache
[2024-12-19T15:04:04.098+0900] {taskinstance.py:1935} ERROR - Task failed with exception
Traceback (most recent call last):
  File "/home/airflow/.local/lib/python3.10/site-packages/airflow/operators/python.py", line 192, in execute
    return_value = self.execute_callable()
  File "/home/airflow/.local/lib/python3.10/site-packages/airflow/operators/python.py", line 209, in execute_callable
    return self.python_callable(*self.op_args, **self.op_kwargs)
  File "/code/plugins/post_crawling.py", line 1909, in post_main
    for url, job_title, company, post_title in added_data:
  File "/code/plugins/post_crawling.py", line 157, in jumpit_crawling
  File "/home/airflow/.local/lib/python3.10/site-packages/selenium/webdriver/chrome/webdriver.py", line 45, in __init__
    super().__init__(
  File "/home/airflow/.local/lib/python3.10/site-packages/selenium/webdriver/chromium/webdriver.py", line 66, in __init__
    super().__init__(command_executor=executor, options=options)
  File "/home/airflow/.local/lib/python3.10/site-packages/selenium/webdriver/remote/webdriver.py", line 241, in __init__
    self.start_session(capabilities)
  File "/home/airflow/.local/lib/python3.10/site-packages/selenium/webdriver/remote/webdriver.py", line 329, in start_session
    response = self.execute(Command.NEW_SESSION, caps)["value"]
  File "/home/airflow/.local/lib/python3.10/site-packages/selenium/webdriver/remote/webdriver.py", line 384, in execute
    self.error_handler.check_response(response)
  File "/home/airflow/.local/lib/python3.10/site-packages/selenium/webdriver/remote/errorhandler.py", line 232, in check_response
    raise exception_class(message, screen, stacktrace)
selenium.common.exceptions.SessionNotCreatedException: Message: session not created: Chrome failed to start: exited normally.
  (session not created: DevToolsActivePort file doesn't exist)
  (The process started from chrome location /opt/google/chrome/chrome is no longer running, so ChromeDriver is assuming that Chrome has crashed.)
Stacktrace:
#0 0x5577cc60d8fa <unknown>
#1 0x5577cc11ed20 <unknown>
#2 0x5577cc156438 <unknown>
#3 0x5577cc151f96 <unknown>
#4 0x5577cc19dd86 <unknown>
#5 0x5577cc19d3d6 <unknown>
#6 0x5577cc191893 <unknown>
#7 0x5577cc16030d <unknown>
#8 0x5577cc16132e <unknown>
#9 0x5577cc5da00b <unknown>
#10 0x5577cc5ddf97 <unknown>
#11 0x5577cc5c671c <unknown>
#12 0x5577cc5deb17 <unknown>
#13 0x5577cc5ab6cf <unknown>
#14 0x5577cc5fc6b8 <unknown>
#15 0x5577cc5fc880 <unknown>
#16 0x5577cc60c776 <unknown>
#17 0x7f93a4dacea7 start_thread

[2024-12-19T15:04:04.107+0900] {taskinstance.py:1398} INFO - Marking task as UP_FOR_RETRY. dag_id=dag_crawling_to_db, task_id=post_crawl, execution_date=20241219T051428, start_date=20241219T060402, end_date=20241219T060404
[2024-12-19T15:04:04.118+0900] {standard_task_runner.py:104} ERROR - Failed to execute job 10 for task post_crawl (Message: session not created: Chrome failed to start: exited normally.
  (session not created: DevToolsActivePort file doesn't exist)
  (The process started from chrome location /opt/google/chrome/chrome is no longer running, so ChromeDriver is assuming that Chrome has crashed.)
Stacktrace:
#0 0x5577cc60d8fa <unknown>
#1 0x5577cc11ed20 <unknown>
#2 0x5577cc156438 <unknown>
#3 0x5577cc151f96 <unknown>
#4 0x5577cc19dd86 <unknown>
#5 0x5577cc19d3d6 <unknown>
#6 0x5577cc191893 <unknown>
#7 0x5577cc16030d <unknown>
#8 0x5577cc16132e <unknown>
#9 0x5577cc5da00b <unknown>
#10 0x5577cc5ddf97 <unknown>
#11 0x5577cc5c671c <unknown>
#12 0x5577cc5deb17 <unknown>
#13 0x5577cc5ab6cf <unknown>
#14 0x5577cc5fc6b8 <unknown>
#15 0x5577cc5fc880 <unknown>
#16 0x5577cc60c776 <unknown>
#17 0x7f93a4dacea7 start_thread
; 863)
[2024-12-19T15:04:04.145+0900] {local_task_job_runner.py:228} INFO - Task exited with return code 1
[2024-12-19T15:04:04.165+0900] {taskinstance.py:2776} INFO - 0 downstream tasks scheduled from follow-on schedule check
