[2024-12-19T14:56:58.579+0900] {taskinstance.py:1157} INFO - Dependencies all met for dep_context=non-requeueable deps ti=<TaskInstance: dag_crawling_to_db.post_crawl manual__2024-12-19T05:14:28+00:00 [queued]>
[2024-12-19T14:56:58.589+0900] {taskinstance.py:1157} INFO - Dependencies all met for dep_context=requeueable deps ti=<TaskInstance: dag_crawling_to_db.post_crawl manual__2024-12-19T05:14:28+00:00 [queued]>
[2024-12-19T14:56:58.590+0900] {taskinstance.py:1359} INFO - Starting attempt 6 of 6
[2024-12-19T14:56:58.604+0900] {taskinstance.py:1380} INFO - Executing <Task(PythonOperator): post_crawl> on 2024-12-19 05:14:28+00:00
[2024-12-19T14:56:58.608+0900] {standard_task_runner.py:57} INFO - Started process 750 to run task
[2024-12-19T14:56:58.611+0900] {standard_task_runner.py:84} INFO - Running: ['***', 'tasks', 'run', 'dag_crawling_to_db', 'post_crawl', 'manual__2024-12-19T05:14:28+00:00', '--job-id', '9', '--raw', '--subdir', 'DAGS_FOLDER/dag_crawling_to_db.py', '--cfg-path', '/tmp/tmpvhsjpxvy']
[2024-12-19T14:56:58.613+0900] {standard_task_runner.py:85} INFO - Job 9: Subtask post_crawl
[2024-12-19T14:56:58.659+0900] {task_command.py:415} INFO - Running <TaskInstance: dag_crawling_to_db.post_crawl manual__2024-12-19T05:14:28+00:00 [running]> on host 937402c51523
[2024-12-19T14:56:58.729+0900] {taskinstance.py:1660} INFO - Exporting env vars: AIRFLOW_CTX_DAG_OWNER='***' AIRFLOW_CTX_DAG_ID='dag_crawling_to_db' AIRFLOW_CTX_TASK_ID='post_crawl' AIRFLOW_CTX_EXECUTION_DATE='2024-12-19T05:14:28+00:00' AIRFLOW_CTX_TRY_NUMBER='6' AIRFLOW_CTX_DAG_RUN_ID='manual__2024-12-19T05:14:28+00:00'
[2024-12-19T14:56:58.730+0900] {logging_mixin.py:151} INFO - 점핏 시작 시간: 2024-12-19 14:56:58
[2024-12-19T14:56:58.745+0900] {credentials.py:1254} INFO - Found credentials in shared credentials file: /code/.aws/credentials
[2024-12-19T14:56:59.133+0900] {logging_mixin.py:151} INFO - Error reading file from S3: An error occurred (NoSuchKey) when calling the GetObject operation: The specified key does not exist.
[2024-12-19T14:56:59.236+0900] {logger.py:11} INFO - ====== WebDriver manager ======
[2024-12-19T14:56:59.295+0900] {logger.py:11} INFO - Get LATEST chromedriver version for google-chrome
[2024-12-19T14:56:59.369+0900] {logger.py:11} INFO - Get LATEST chromedriver version for google-chrome
[2024-12-19T14:56:59.445+0900] {logger.py:11} INFO - Driver [/home/***/.wdm/drivers/chromedriver/linux64/131.0.6778.204/chromedriver-linux64/chromedriver] found in cache
[2024-12-19T14:56:59.695+0900] {taskinstance.py:1935} ERROR - Task failed with exception
Traceback (most recent call last):
  File "/home/airflow/.local/lib/python3.10/site-packages/airflow/operators/python.py", line 192, in execute
    return_value = self.execute_callable()
  File "/home/airflow/.local/lib/python3.10/site-packages/airflow/operators/python.py", line 209, in execute_callable
    return self.python_callable(*self.op_args, **self.op_kwargs)
  File "/code/plugins/post_crawling.py", line 1909, in post_main
    def post_main():
  File "/code/plugins/post_crawling.py", line 157, in jumpit_crawling
    options = Options()
  File "/home/airflow/.local/lib/python3.10/site-packages/selenium/webdriver/chrome/webdriver.py", line 45, in __init__
    super().__init__(
  File "/home/airflow/.local/lib/python3.10/site-packages/selenium/webdriver/chromium/webdriver.py", line 66, in __init__
    super().__init__(command_executor=executor, options=options)
  File "/home/airflow/.local/lib/python3.10/site-packages/selenium/webdriver/remote/webdriver.py", line 241, in __init__
    self.start_session(capabilities)
  File "/home/airflow/.local/lib/python3.10/site-packages/selenium/webdriver/remote/webdriver.py", line 329, in start_session
    response = self.execute(Command.NEW_SESSION, caps)["value"]
  File "/home/airflow/.local/lib/python3.10/site-packages/selenium/webdriver/remote/webdriver.py", line 384, in execute
    self.error_handler.check_response(response)
  File "/home/airflow/.local/lib/python3.10/site-packages/selenium/webdriver/remote/errorhandler.py", line 232, in check_response
    raise exception_class(message, screen, stacktrace)
selenium.common.exceptions.SessionNotCreatedException: Message: session not created: Chrome failed to start: exited normally.
  (session not created: DevToolsActivePort file doesn't exist)
  (The process started from chrome location /opt/google/chrome/chrome is no longer running, so ChromeDriver is assuming that Chrome has crashed.)
Stacktrace:
#0 0x55796d4758fa <unknown>
#1 0x55796cf86d20 <unknown>
#2 0x55796cfbe438 <unknown>
#3 0x55796cfb9f96 <unknown>
#4 0x55796d005d86 <unknown>
#5 0x55796d0053d6 <unknown>
#6 0x55796cff9893 <unknown>
#7 0x55796cfc830d <unknown>
#8 0x55796cfc932e <unknown>
#9 0x55796d44200b <unknown>
#10 0x55796d445f97 <unknown>
#11 0x55796d42e71c <unknown>
#12 0x55796d446b17 <unknown>
#13 0x55796d4136cf <unknown>
#14 0x55796d4646b8 <unknown>
#15 0x55796d464880 <unknown>
#16 0x55796d474776 <unknown>
#17 0x7f8d35ebbea7 start_thread

[2024-12-19T14:56:59.704+0900] {taskinstance.py:1398} INFO - Marking task as FAILED. dag_id=dag_crawling_to_db, task_id=post_crawl, execution_date=20241219T051428, start_date=20241219T055658, end_date=20241219T055659
[2024-12-19T14:56:59.716+0900] {standard_task_runner.py:104} ERROR - Failed to execute job 9 for task post_crawl (Message: session not created: Chrome failed to start: exited normally.
  (session not created: DevToolsActivePort file doesn't exist)
  (The process started from chrome location /opt/google/chrome/chrome is no longer running, so ChromeDriver is assuming that Chrome has crashed.)
Stacktrace:
#0 0x55796d4758fa <unknown>
#1 0x55796cf86d20 <unknown>
#2 0x55796cfbe438 <unknown>
#3 0x55796cfb9f96 <unknown>
#4 0x55796d005d86 <unknown>
#5 0x55796d0053d6 <unknown>
#6 0x55796cff9893 <unknown>
#7 0x55796cfc830d <unknown>
#8 0x55796cfc932e <unknown>
#9 0x55796d44200b <unknown>
#10 0x55796d445f97 <unknown>
#11 0x55796d42e71c <unknown>
#12 0x55796d446b17 <unknown>
#13 0x55796d4136cf <unknown>
#14 0x55796d4646b8 <unknown>
#15 0x55796d464880 <unknown>
#16 0x55796d474776 <unknown>
#17 0x7f8d35ebbea7 start_thread
; 750)
[2024-12-19T14:56:59.750+0900] {local_task_job_runner.py:228} INFO - Task exited with return code 1
[2024-12-19T14:56:59.771+0900] {taskinstance.py:2776} INFO - 0 downstream tasks scheduled from follow-on schedule check
