[2024-12-19T12:32:08.428+0900] {taskinstance.py:1157} INFO - Dependencies all met for dep_context=non-requeueable deps ti=<TaskInstance: dag_crawling_to_db.post_crawl manual__2024-12-19T03:22:56+00:00 [queued]>
[2024-12-19T12:32:08.437+0900] {taskinstance.py:1157} INFO - Dependencies all met for dep_context=requeueable deps ti=<TaskInstance: dag_crawling_to_db.post_crawl manual__2024-12-19T03:22:56+00:00 [queued]>
[2024-12-19T12:32:08.437+0900] {taskinstance.py:1359} INFO - Starting attempt 4 of 5
[2024-12-19T12:32:08.452+0900] {taskinstance.py:1380} INFO - Executing <Task(PythonOperator): post_crawl> on 2024-12-19 03:22:56+00:00
[2024-12-19T12:32:08.458+0900] {standard_task_runner.py:57} INFO - Started process 295 to run task
[2024-12-19T12:32:08.460+0900] {standard_task_runner.py:84} INFO - Running: ['***', 'tasks', 'run', 'dag_crawling_to_db', 'post_crawl', 'manual__2024-12-19T03:22:56+00:00', '--job-id', '8', '--raw', '--subdir', 'DAGS_FOLDER/dag_crawling_to_db.py', '--cfg-path', '/tmp/tmpu3cx41b3']
[2024-12-19T12:32:08.463+0900] {standard_task_runner.py:85} INFO - Job 8: Subtask post_crawl
[2024-12-19T12:32:08.506+0900] {task_command.py:415} INFO - Running <TaskInstance: dag_crawling_to_db.post_crawl manual__2024-12-19T03:22:56+00:00 [running]> on host 9e2fe3889768
[2024-12-19T12:32:08.573+0900] {taskinstance.py:1660} INFO - Exporting env vars: AIRFLOW_CTX_DAG_OWNER='***' AIRFLOW_CTX_DAG_ID='dag_crawling_to_db' AIRFLOW_CTX_TASK_ID='post_crawl' AIRFLOW_CTX_EXECUTION_DATE='2024-12-19T03:22:56+00:00' AIRFLOW_CTX_TRY_NUMBER='4' AIRFLOW_CTX_DAG_RUN_ID='manual__2024-12-19T03:22:56+00:00'
[2024-12-19T12:32:08.574+0900] {logging_mixin.py:151} INFO - 점핏 시작 시간: 2024-12-19 12:32:08
[2024-12-19T12:32:08.589+0900] {credentials.py:1254} INFO - Found credentials in shared credentials file: /code/.aws/credentials
[2024-12-19T12:32:09.051+0900] {logging_mixin.py:151} INFO - Error reading file from S3: An error occurred (NoSuchKey) when calling the GetObject operation: The specified key does not exist.
[2024-12-19T12:32:09.160+0900] {logger.py:11} INFO - ====== WebDriver manager ======
[2024-12-19T12:32:09.218+0900] {logger.py:11} INFO - Get LATEST chromedriver version for google-chrome
[2024-12-19T12:32:09.285+0900] {logger.py:11} INFO - Get LATEST chromedriver version for google-chrome
[2024-12-19T12:32:09.357+0900] {logger.py:11} INFO - Driver [/home/***/.wdm/drivers/chromedriver/linux64/131.0.6778.204/chromedriver-linux64/chromedriver] found in cache
[2024-12-19T12:32:09.596+0900] {taskinstance.py:1935} ERROR - Task failed with exception
Traceback (most recent call last):
  File "/home/airflow/.local/lib/python3.10/site-packages/airflow/operators/python.py", line 192, in execute
    return_value = self.execute_callable()
  File "/home/airflow/.local/lib/python3.10/site-packages/airflow/operators/python.py", line 209, in execute_callable
    return self.python_callable(*self.op_args, **self.op_kwargs)
  File "/code/plugins/post_crawling.py", line 1909, in post_main
    jumpit_crawling()
  File "/code/plugins/post_crawling.py", line 157, in jumpit_crawling
    driver = webdriver.Chrome(service=Service(ChromeDriverManager().install()), options=options)
  File "/home/airflow/.local/lib/python3.10/site-packages/selenium/webdriver/chrome/webdriver.py", line 45, in __init__
    super().__init__(
  File "/home/airflow/.local/lib/python3.10/site-packages/selenium/webdriver/chromium/webdriver.py", line 66, in __init__
    super().__init__(command_executor=executor, options=options)
  File "/home/airflow/.local/lib/python3.10/site-packages/selenium/webdriver/remote/webdriver.py", line 241, in __init__
    self.start_session(capabilities)
  File "/home/airflow/.local/lib/python3.10/site-packages/selenium/webdriver/remote/webdriver.py", line 329, in start_session
    response = self.execute(Command.NEW_SESSION, caps)["value"]
  File "/home/airflow/.local/lib/python3.10/site-packages/selenium/webdriver/remote/webdriver.py", line 384, in execute
    self.error_handler.check_response(response)
  File "/home/airflow/.local/lib/python3.10/site-packages/selenium/webdriver/remote/errorhandler.py", line 232, in check_response
    raise exception_class(message, screen, stacktrace)
selenium.common.exceptions.SessionNotCreatedException: Message: session not created: Chrome failed to start: exited normally.
  (session not created: DevToolsActivePort file doesn't exist)
  (The process started from chrome location /opt/google/chrome/chrome is no longer running, so ChromeDriver is assuming that Chrome has crashed.)
Stacktrace:
#0 0x56425ef318fa <unknown>
#1 0x56425ea42d20 <unknown>
#2 0x56425ea7a438 <unknown>
#3 0x56425ea75f96 <unknown>
#4 0x56425eac1d86 <unknown>
#5 0x56425eac13d6 <unknown>
#6 0x56425eab5893 <unknown>
#7 0x56425ea8430d <unknown>
#8 0x56425ea8532e <unknown>
#9 0x56425eefe00b <unknown>
#10 0x56425ef01f97 <unknown>
#11 0x56425eeea71c <unknown>
#12 0x56425ef02b17 <unknown>
#13 0x56425eecf6cf <unknown>
#14 0x56425ef206b8 <unknown>
#15 0x56425ef20880 <unknown>
#16 0x56425ef30776 <unknown>
#17 0x7f4bdc05fea7 start_thread

[2024-12-19T12:32:09.606+0900] {taskinstance.py:1398} INFO - Marking task as UP_FOR_RETRY. dag_id=dag_crawling_to_db, task_id=post_crawl, execution_date=20241219T032256, start_date=20241219T033208, end_date=20241219T033209
[2024-12-19T12:32:09.618+0900] {standard_task_runner.py:104} ERROR - Failed to execute job 8 for task post_crawl (Message: session not created: Chrome failed to start: exited normally.
  (session not created: DevToolsActivePort file doesn't exist)
  (The process started from chrome location /opt/google/chrome/chrome is no longer running, so ChromeDriver is assuming that Chrome has crashed.)
Stacktrace:
#0 0x56425ef318fa <unknown>
#1 0x56425ea42d20 <unknown>
#2 0x56425ea7a438 <unknown>
#3 0x56425ea75f96 <unknown>
#4 0x56425eac1d86 <unknown>
#5 0x56425eac13d6 <unknown>
#6 0x56425eab5893 <unknown>
#7 0x56425ea8430d <unknown>
#8 0x56425ea8532e <unknown>
#9 0x56425eefe00b <unknown>
#10 0x56425ef01f97 <unknown>
#11 0x56425eeea71c <unknown>
#12 0x56425ef02b17 <unknown>
#13 0x56425eecf6cf <unknown>
#14 0x56425ef206b8 <unknown>
#15 0x56425ef20880 <unknown>
#16 0x56425ef30776 <unknown>
#17 0x7f4bdc05fea7 start_thread
; 295)
[2024-12-19T12:32:09.640+0900] {local_task_job_runner.py:228} INFO - Task exited with return code 1
[2024-12-19T12:32:09.661+0900] {taskinstance.py:2776} INFO - 0 downstream tasks scheduled from follow-on schedule check
