[2024-12-19T12:28:28.321+0900] {taskinstance.py:1157} INFO - Dependencies all met for dep_context=non-requeueable deps ti=<TaskInstance: dag_crawling_to_db.post_crawl manual__2024-12-19T03:22:56+00:00 [queued]>
[2024-12-19T12:28:28.329+0900] {taskinstance.py:1157} INFO - Dependencies all met for dep_context=requeueable deps ti=<TaskInstance: dag_crawling_to_db.post_crawl manual__2024-12-19T03:22:56+00:00 [queued]>
[2024-12-19T12:28:28.329+0900] {taskinstance.py:1359} INFO - Starting attempt 2 of 3
[2024-12-19T12:28:28.343+0900] {taskinstance.py:1380} INFO - Executing <Task(PythonOperator): post_crawl> on 2024-12-19 03:22:56+00:00
[2024-12-19T12:28:28.347+0900] {standard_task_runner.py:57} INFO - Started process 173 to run task
[2024-12-19T12:28:28.350+0900] {standard_task_runner.py:84} INFO - Running: ['***', 'tasks', 'run', 'dag_crawling_to_db', 'post_crawl', 'manual__2024-12-19T03:22:56+00:00', '--job-id', '6', '--raw', '--subdir', 'DAGS_FOLDER/dag_crawling_to_db.py', '--cfg-path', '/tmp/tmp1z1urhl5']
[2024-12-19T12:28:28.353+0900] {standard_task_runner.py:85} INFO - Job 6: Subtask post_crawl
[2024-12-19T12:28:28.395+0900] {task_command.py:415} INFO - Running <TaskInstance: dag_crawling_to_db.post_crawl manual__2024-12-19T03:22:56+00:00 [running]> on host 9e2fe3889768
[2024-12-19T12:28:28.464+0900] {taskinstance.py:1660} INFO - Exporting env vars: AIRFLOW_CTX_DAG_OWNER='***' AIRFLOW_CTX_DAG_ID='dag_crawling_to_db' AIRFLOW_CTX_TASK_ID='post_crawl' AIRFLOW_CTX_EXECUTION_DATE='2024-12-19T03:22:56+00:00' AIRFLOW_CTX_TRY_NUMBER='2' AIRFLOW_CTX_DAG_RUN_ID='manual__2024-12-19T03:22:56+00:00'
[2024-12-19T12:28:28.465+0900] {logging_mixin.py:151} INFO - 점핏 시작 시간: 2024-12-19 12:28:28
[2024-12-19T12:28:28.482+0900] {credentials.py:1254} INFO - Found credentials in shared credentials file: /code/.aws/credentials
[2024-12-19T12:28:28.899+0900] {logging_mixin.py:151} INFO - Error reading file from S3: An error occurred (NoSuchKey) when calling the GetObject operation: The specified key does not exist.
[2024-12-19T12:28:28.992+0900] {logger.py:11} INFO - ====== WebDriver manager ======
[2024-12-19T12:28:29.060+0900] {logger.py:11} INFO - Get LATEST chromedriver version for google-chrome
[2024-12-19T12:28:29.138+0900] {logger.py:11} INFO - Get LATEST chromedriver version for google-chrome
[2024-12-19T12:28:29.233+0900] {logger.py:11} INFO - There is no [linux64] chromedriver "131.0.6778.204" for browser google-chrome "131.0.6778" in cache
[2024-12-19T12:28:29.235+0900] {logger.py:11} INFO - Get LATEST chromedriver version for google-chrome
[2024-12-19T12:28:29.444+0900] {logger.py:11} INFO - WebDriver version 131.0.6778.204 selected
[2024-12-19T12:28:29.447+0900] {logger.py:11} INFO - Modern chrome version https://storage.googleapis.com/chrome-for-testing-public/131.0.6778.204/linux64/chromedriver-linux64.zip
[2024-12-19T12:28:29.448+0900] {logger.py:11} INFO - About to download new driver from https://storage.googleapis.com/chrome-for-testing-public/131.0.6778.204/linux64/chromedriver-linux64.zip
[2024-12-19T12:28:29.578+0900] {logger.py:11} INFO - Driver downloading response is 200
[2024-12-19T12:28:29.910+0900] {logger.py:11} INFO - Get LATEST chromedriver version for google-chrome
[2024-12-19T12:28:30.089+0900] {logger.py:11} INFO - Driver has been saved in cache [/home/***/.wdm/drivers/chromedriver/linux64/131.0.6778.204]
[2024-12-19T12:28:30.339+0900] {taskinstance.py:1935} ERROR - Task failed with exception
Traceback (most recent call last):
  File "/home/airflow/.local/lib/python3.10/site-packages/airflow/operators/python.py", line 192, in execute
    return_value = self.execute_callable()
  File "/home/airflow/.local/lib/python3.10/site-packages/airflow/operators/python.py", line 209, in execute_callable
    return self.python_callable(*self.op_args, **self.op_kwargs)
  File "/code/plugins/post_crawling.py", line 1909, in post_main
    jumpit_crawling()
  File "/code/plugins/post_crawling.py", line 157, in jumpit_crawling
    driver = webdriver.Chrome(service=Service(ChromeDriverManager().install()), options=options)
  File "/home/airflow/.local/lib/python3.10/site-packages/selenium/webdriver/chrome/webdriver.py", line 45, in __init__
    super().__init__(
  File "/home/airflow/.local/lib/python3.10/site-packages/selenium/webdriver/chromium/webdriver.py", line 66, in __init__
    super().__init__(command_executor=executor, options=options)
  File "/home/airflow/.local/lib/python3.10/site-packages/selenium/webdriver/remote/webdriver.py", line 241, in __init__
    self.start_session(capabilities)
  File "/home/airflow/.local/lib/python3.10/site-packages/selenium/webdriver/remote/webdriver.py", line 329, in start_session
    response = self.execute(Command.NEW_SESSION, caps)["value"]
  File "/home/airflow/.local/lib/python3.10/site-packages/selenium/webdriver/remote/webdriver.py", line 384, in execute
    self.error_handler.check_response(response)
  File "/home/airflow/.local/lib/python3.10/site-packages/selenium/webdriver/remote/errorhandler.py", line 232, in check_response
    raise exception_class(message, screen, stacktrace)
selenium.common.exceptions.SessionNotCreatedException: Message: session not created: Chrome failed to start: exited normally.
  (session not created: DevToolsActivePort file doesn't exist)
  (The process started from chrome location /opt/google/chrome/chrome is no longer running, so ChromeDriver is assuming that Chrome has crashed.)
Stacktrace:
#0 0x55e3ecebc8fa <unknown>
#1 0x55e3ec9cdd20 <unknown>
#2 0x55e3eca05438 <unknown>
#3 0x55e3eca00f96 <unknown>
#4 0x55e3eca4cd86 <unknown>
#5 0x55e3eca4c3d6 <unknown>
#6 0x55e3eca40893 <unknown>
#7 0x55e3eca0f30d <unknown>
#8 0x55e3eca1032e <unknown>
#9 0x55e3ece8900b <unknown>
#10 0x55e3ece8cf97 <unknown>
#11 0x55e3ece7571c <unknown>
#12 0x55e3ece8db17 <unknown>
#13 0x55e3ece5a6cf <unknown>
#14 0x55e3eceab6b8 <unknown>
#15 0x55e3eceab880 <unknown>
#16 0x55e3ecebb776 <unknown>
#17 0x7f7eeb071ea7 start_thread

[2024-12-19T12:28:30.347+0900] {taskinstance.py:1398} INFO - Marking task as UP_FOR_RETRY. dag_id=dag_crawling_to_db, task_id=post_crawl, execution_date=20241219T032256, start_date=20241219T032828, end_date=20241219T032830
[2024-12-19T12:28:30.373+0900] {standard_task_runner.py:104} ERROR - Failed to execute job 6 for task post_crawl (Message: session not created: Chrome failed to start: exited normally.
  (session not created: DevToolsActivePort file doesn't exist)
  (The process started from chrome location /opt/google/chrome/chrome is no longer running, so ChromeDriver is assuming that Chrome has crashed.)
Stacktrace:
#0 0x55e3ecebc8fa <unknown>
#1 0x55e3ec9cdd20 <unknown>
#2 0x55e3eca05438 <unknown>
#3 0x55e3eca00f96 <unknown>
#4 0x55e3eca4cd86 <unknown>
#5 0x55e3eca4c3d6 <unknown>
#6 0x55e3eca40893 <unknown>
#7 0x55e3eca0f30d <unknown>
#8 0x55e3eca1032e <unknown>
#9 0x55e3ece8900b <unknown>
#10 0x55e3ece8cf97 <unknown>
#11 0x55e3ece7571c <unknown>
#12 0x55e3ece8db17 <unknown>
#13 0x55e3ece5a6cf <unknown>
#14 0x55e3eceab6b8 <unknown>
#15 0x55e3eceab880 <unknown>
#16 0x55e3ecebb776 <unknown>
#17 0x7f7eeb071ea7 start_thread
; 173)
[2024-12-19T12:28:30.414+0900] {local_task_job_runner.py:228} INFO - Task exited with return code 1
[2024-12-19T12:28:30.444+0900] {taskinstance.py:2776} INFO - 0 downstream tasks scheduled from follow-on schedule check
