[2024-12-20T23:23:50.128+0900] {taskinstance.py:1157} INFO - Dependencies all met for dep_context=non-requeueable deps ti=<TaskInstance: dag_crawling_to_db.post_crawl manual__2024-12-20T14:21:58+00:00 [queued]>
[2024-12-20T23:23:50.140+0900] {taskinstance.py:1157} INFO - Dependencies all met for dep_context=requeueable deps ti=<TaskInstance: dag_crawling_to_db.post_crawl manual__2024-12-20T14:21:58+00:00 [queued]>
[2024-12-20T23:23:50.140+0900] {taskinstance.py:1359} INFO - Starting attempt 2 of 2
[2024-12-20T23:23:50.154+0900] {taskinstance.py:1380} INFO - Executing <Task(PythonOperator): post_crawl> on 2024-12-20 14:21:58+00:00
[2024-12-20T23:23:50.157+0900] {standard_task_runner.py:57} INFO - Started process 140 to run task
[2024-12-20T23:23:50.160+0900] {standard_task_runner.py:84} INFO - Running: ['***', 'tasks', 'run', 'dag_crawling_to_db', 'post_crawl', 'manual__2024-12-20T14:21:58+00:00', '--job-id', '10', '--raw', '--subdir', 'DAGS_FOLDER/dag_crawling_to_db.py', '--cfg-path', '/tmp/tmpspkquwcc']
[2024-12-20T23:23:50.162+0900] {standard_task_runner.py:85} INFO - Job 10: Subtask post_crawl
[2024-12-20T23:23:50.197+0900] {task_command.py:415} INFO - Running <TaskInstance: dag_crawling_to_db.post_crawl manual__2024-12-20T14:21:58+00:00 [running]> on host 6cc4d0fc5740
[2024-12-20T23:23:50.277+0900] {taskinstance.py:1660} INFO - Exporting env vars: AIRFLOW_CTX_DAG_OWNER='***' AIRFLOW_CTX_DAG_ID='dag_crawling_to_db' AIRFLOW_CTX_TASK_ID='post_crawl' AIRFLOW_CTX_EXECUTION_DATE='2024-12-20T14:21:58+00:00' AIRFLOW_CTX_TRY_NUMBER='2' AIRFLOW_CTX_DAG_RUN_ID='manual__2024-12-20T14:21:58+00:00'
[2024-12-20T23:23:50.279+0900] {logging_mixin.py:151} INFO - 점핏 시작 시간: 2024-12-20 23:23:50
[2024-12-20T23:24:00.391+0900] {taskinstance.py:1935} ERROR - Task failed with exception
Traceback (most recent call last):
  File "/home/airflow/.local/lib/python3.10/site-packages/pymysql/connections.py", line 649, in connect
    sock = socket.create_connection(
  File "/usr/local/lib/python3.10/socket.py", line 845, in create_connection
    raise err
  File "/usr/local/lib/python3.10/socket.py", line 833, in create_connection
    sock.connect(sa)
TimeoutError: timed out

During handling of the above exception, another exception occurred:

Traceback (most recent call last):
  File "/home/airflow/.local/lib/python3.10/site-packages/airflow/operators/python.py", line 192, in execute
    return_value = self.execute_callable()
  File "/home/airflow/.local/lib/python3.10/site-packages/airflow/operators/python.py", line 209, in execute_callable
    return self.python_callable(*self.op_args, **self.op_kwargs)
  File "/code/plugins/post_crawling.py", line 2005, in post_main
    jumpit_crawling()
  File "/code/plugins/post_crawling.py", line 158, in jumpit_crawling
    connection = pymysql.connect(
  File "/home/airflow/.local/lib/python3.10/site-packages/pymysql/connections.py", line 361, in __init__
    self.connect()
  File "/home/airflow/.local/lib/python3.10/site-packages/pymysql/connections.py", line 716, in connect
    raise exc
pymysql.err.OperationalError: (2003, "Can't connect to MySQL server on 't2rds.cfa60ymesotv.ap-northeast-2.rds.amazonaws.com' (timed out)")
[2024-12-20T23:24:00.400+0900] {taskinstance.py:1398} INFO - Marking task as FAILED. dag_id=dag_crawling_to_db, task_id=post_crawl, execution_date=20241220T142158, start_date=20241220T142350, end_date=20241220T142400
[2024-12-20T23:24:00.418+0900] {standard_task_runner.py:104} ERROR - Failed to execute job 10 for task post_crawl ((2003, "Can't connect to MySQL server on 't2rds.cfa60ymesotv.ap-northeast-2.rds.amazonaws.com' (timed out)"); 140)
[2024-12-20T23:24:00.457+0900] {local_task_job_runner.py:228} INFO - Task exited with return code 1
[2024-12-20T23:24:00.480+0900] {taskinstance.py:2776} INFO - 0 downstream tasks scheduled from follow-on schedule check
