[2024-12-21T00:12:38.621+0900] {taskinstance.py:1157} INFO - Dependencies all met for dep_context=non-requeueable deps ti=<TaskInstance: dag_crawling_to_db.link_crawl manual__2024-12-20T15:12:27+00:00 [queued]>
[2024-12-21T00:12:38.629+0900] {taskinstance.py:1157} INFO - Dependencies all met for dep_context=requeueable deps ti=<TaskInstance: dag_crawling_to_db.link_crawl manual__2024-12-20T15:12:27+00:00 [queued]>
[2024-12-21T00:12:38.630+0900] {taskinstance.py:1359} INFO - Starting attempt 1 of 2
[2024-12-21T00:12:38.642+0900] {taskinstance.py:1380} INFO - Executing <Task(PythonOperator): link_crawl> on 2024-12-20 15:12:27+00:00
[2024-12-21T00:12:38.645+0900] {standard_task_runner.py:57} INFO - Started process 116 to run task
[2024-12-21T00:12:38.648+0900] {standard_task_runner.py:84} INFO - Running: ['***', 'tasks', 'run', 'dag_crawling_to_db', 'link_crawl', 'manual__2024-12-20T15:12:27+00:00', '--job-id', '19', '--raw', '--subdir', 'DAGS_FOLDER/dag_crawling_to_db.py', '--cfg-path', '/tmp/tmpyi0f7kcu']
[2024-12-21T00:12:38.651+0900] {standard_task_runner.py:85} INFO - Job 19: Subtask link_crawl
[2024-12-21T00:12:38.691+0900] {task_command.py:415} INFO - Running <TaskInstance: dag_crawling_to_db.link_crawl manual__2024-12-20T15:12:27+00:00 [running]> on host a617ee149c5c
[2024-12-21T00:12:38.764+0900] {taskinstance.py:1660} INFO - Exporting env vars: AIRFLOW_CTX_DAG_OWNER='***' AIRFLOW_CTX_DAG_ID='dag_crawling_to_db' AIRFLOW_CTX_TASK_ID='link_crawl' AIRFLOW_CTX_EXECUTION_DATE='2024-12-20T15:12:27+00:00' AIRFLOW_CTX_TRY_NUMBER='1' AIRFLOW_CTX_DAG_RUN_ID='manual__2024-12-20T15:12:27+00:00'
[2024-12-21T00:12:38.764+0900] {logging_mixin.py:151} INFO - 인크루트url 시작 시간: 2024-12-21 00:12:38
[2024-12-21T00:12:38.765+0900] {logging_mixin.py:151} INFO - /code/plugins/incruit
[2024-12-21T00:15:36.873+0900] {logging_mixin.py:151} INFO - 인크루트url 종료 시간: 2024-12-21 00:15:36
[2024-12-21T00:15:41.874+0900] {logging_mixin.py:151} INFO - 잡코리아url 시작 시간: 2024-12-21 00:15:41
[2024-12-21T00:15:41.900+0900] {credentials.py:1254} INFO - Found credentials in shared credentials file: /code/.aws/credentials
[2024-12-21T00:15:42.024+0900] {logger.py:11} INFO - ====== WebDriver manager ======
[2024-12-21T00:15:42.089+0900] {logger.py:11} INFO - Get LATEST chromedriver version for google-chrome
[2024-12-21T00:15:42.329+0900] {logger.py:11} INFO - Get LATEST chromedriver version for google-chrome
[2024-12-21T00:15:42.629+0900] {logger.py:11} INFO - There is no [linux64] chromedriver "131.0.6778.204" for browser google-chrome "131.0.6778" in cache
[2024-12-21T00:15:42.629+0900] {logger.py:11} INFO - Get LATEST chromedriver version for google-chrome
[2024-12-21T00:15:43.136+0900] {logger.py:11} INFO - WebDriver version 131.0.6778.204 selected
[2024-12-21T00:15:43.140+0900] {logger.py:11} INFO - Modern chrome version https://storage.googleapis.com/chrome-for-testing-public/131.0.6778.204/linux64/chromedriver-linux64.zip
[2024-12-21T00:15:43.140+0900] {logger.py:11} INFO - About to download new driver from https://storage.googleapis.com/chrome-for-testing-public/131.0.6778.204/linux64/chromedriver-linux64.zip
[2024-12-21T00:15:43.379+0900] {logger.py:11} INFO - Driver downloading response is 200
[2024-12-21T00:15:44.603+0900] {logger.py:11} INFO - Get LATEST chromedriver version for google-chrome
[2024-12-21T00:15:44.949+0900] {logger.py:11} INFO - Driver has been saved in cache [/home/***/.wdm/drivers/chromedriver/linux64/131.0.6778.204]
[2024-12-21T00:15:45.822+0900] {logging_mixin.py:151} INFO - S3에 오늘 파일이 존재하지 않습니다. 새로 생성합니다.
[2024-12-21T00:15:45.822+0900] {logging_mixin.py:151} INFO - 검색 키워드: 데이터 엔지니어 (DE)
[2024-12-21T00:27:20.844+0900] {logging_mixin.py:151} INFO - 83에 수집할 링크가 없으므로 링크 수집을 멈춥니다.
[2024-12-21T00:27:21.321+0900] {logging_mixin.py:151} INFO - 파일이 S3에 성공적으로 업로드되었습니다. S3 경로: s3://t2jt/job/DE/sources/jobkorea/links/20241221.txt
[2024-12-21T00:27:21.321+0900] {logging_mixin.py:151} INFO - 데이터 엔지니어 (DE)에서 수집한 링크를 S3에 저장했습니다: job/DE/sources/jobkorea/links/20241221.txt
[2024-12-21T00:27:21.322+0900] {logging_mixin.py:151} INFO - 데이터 엔지니어에서 1188개의 새로운 링크를 발견하였습니다.
[2024-12-21T00:27:21.377+0900] {logging_mixin.py:151} INFO - S3에 오늘 파일이 존재하지 않습니다. 새로 생성합니다.
[2024-12-21T00:27:21.377+0900] {logging_mixin.py:151} INFO - 검색 키워드: 프론트엔드 (FE)
[2024-12-21T00:29:29.941+0900] {taskinstance.py:1935} ERROR - Task failed with exception
Traceback (most recent call last):
  File "/home/airflow/.local/lib/python3.10/site-packages/urllib3/connectionpool.py", line 466, in _make_request
    six.raise_from(e, None)
  File "<string>", line 3, in raise_from
  File "/home/airflow/.local/lib/python3.10/site-packages/urllib3/connectionpool.py", line 461, in _make_request
    httplib_response = conn.getresponse()
  File "/usr/local/lib/python3.10/http/client.py", line 1375, in getresponse
    response.begin()
  File "/usr/local/lib/python3.10/http/client.py", line 318, in begin
    version, status, reason = self._read_status()
  File "/usr/local/lib/python3.10/http/client.py", line 279, in _read_status
    line = str(self.fp.readline(_MAXLINE + 1), "iso-8859-1")
  File "/usr/local/lib/python3.10/socket.py", line 705, in readinto
    return self._sock.recv_into(b)
TimeoutError: timed out

During handling of the above exception, another exception occurred:

Traceback (most recent call last):
  File "/home/airflow/.local/lib/python3.10/site-packages/airflow/operators/python.py", line 192, in execute
    return_value = self.execute_callable()
  File "/home/airflow/.local/lib/python3.10/site-packages/airflow/operators/python.py", line 209, in execute_callable
    return self.python_callable(*self.op_args, **self.op_kwargs)
  File "/code/plugins/link_crawling.py", line 958, in link_main
    jobkorea_link()
  File "/code/plugins/link_crawling.py", line 298, in jobkorea_link
    scrape_links()
  File "/code/plugins/link_crawling.py", line 290, in scrape_links
    new_links = scrape_links_for_keyword(keyword, keyword_code, existing_links, bucket_name)
  File "/code/plugins/link_crawling.py", line 232, in scrape_links_for_keyword
    driver.get(url)
  File "/home/airflow/.local/lib/python3.10/site-packages/selenium/webdriver/remote/webdriver.py", line 393, in get
    self.execute(Command.GET, {"url": url})
  File "/home/airflow/.local/lib/python3.10/site-packages/selenium/webdriver/remote/webdriver.py", line 382, in execute
    response = self.command_executor.execute(driver_command, params)
  File "/home/airflow/.local/lib/python3.10/site-packages/selenium/webdriver/remote/remote_connection.py", line 404, in execute
    return self._request(command_info[0], url, body=data)
  File "/home/airflow/.local/lib/python3.10/site-packages/selenium/webdriver/remote/remote_connection.py", line 428, in _request
    response = self._conn.request(method, url, body=body, headers=headers, timeout=self._client_config.timeout)
  File "/home/airflow/.local/lib/python3.10/site-packages/urllib3/request.py", line 78, in request
    return self.request_encode_body(
  File "/home/airflow/.local/lib/python3.10/site-packages/urllib3/request.py", line 170, in request_encode_body
    return self.urlopen(method, url, **extra_kw)
  File "/home/airflow/.local/lib/python3.10/site-packages/urllib3/poolmanager.py", line 376, in urlopen
    response = conn.urlopen(method, u.request_uri, **kw)
  File "/home/airflow/.local/lib/python3.10/site-packages/urllib3/connectionpool.py", line 798, in urlopen
    retries = retries.increment(
  File "/home/airflow/.local/lib/python3.10/site-packages/urllib3/util/retry.py", line 550, in increment
    raise six.reraise(type(error), error, _stacktrace)
  File "/home/airflow/.local/lib/python3.10/site-packages/urllib3/packages/six.py", line 770, in reraise
    raise value
  File "/home/airflow/.local/lib/python3.10/site-packages/urllib3/connectionpool.py", line 714, in urlopen
    httplib_response = self._make_request(
  File "/home/airflow/.local/lib/python3.10/site-packages/urllib3/connectionpool.py", line 468, in _make_request
    self._raise_timeout(err=e, url=url, timeout_value=read_timeout)
  File "/home/airflow/.local/lib/python3.10/site-packages/urllib3/connectionpool.py", line 357, in _raise_timeout
    raise ReadTimeoutError(
urllib3.exceptions.ReadTimeoutError: HTTPConnectionPool(host='localhost', port=40681): Read timed out. (read timeout=120)
[2024-12-21T00:29:29.964+0900] {taskinstance.py:1398} INFO - Marking task as UP_FOR_RETRY. dag_id=dag_crawling_to_db, task_id=link_crawl, execution_date=20241220T151227, start_date=20241220T151238, end_date=20241220T152929
[2024-12-21T00:29:29.979+0900] {standard_task_runner.py:104} ERROR - Failed to execute job 19 for task link_crawl (HTTPConnectionPool(host='localhost', port=40681): Read timed out. (read timeout=120); 116)
[2024-12-21T00:29:29.993+0900] {local_task_job_runner.py:228} INFO - Task exited with return code 1
[2024-12-21T00:29:30.018+0900] {taskinstance.py:2776} INFO - 0 downstream tasks scheduled from follow-on schedule check
